Internal Server Error: /donate
Traceback (most recent call last):
  File "/Users/ughestaff/.local/share/virtualenvs/Codes-vPfYgZ7o/lib/python3.10/site-packages/django/core/handlers/exception.py", line 34, in inner
    response = get_response(request)
  File "/Users/ughestaff/.local/share/virtualenvs/Codes-vPfYgZ7o/lib/python3.10/site-packages/django/core/handlers/base.py", line 126, in _get_response
    response = self.process_exception_by_middleware(e, request)
  File "/Users/ughestaff/.local/share/virtualenvs/Codes-vPfYgZ7o/lib/python3.10/site-packages/django/core/handlers/base.py", line 124, in _get_response
    response = wrapped_callback(request, *callback_args, **callback_kwargs)
  File "/Users/ughestaff/OneDrive - IU International University of Applied Sciences/School/Subjects/In Progress/Project Software Engineering/BloodLoof/2. Development Phase/Codes/donate/views.py", line 28, in donate
    password = request.user.password1
  File "/Users/ughestaff/.local/share/virtualenvs/Codes-vPfYgZ7o/lib/python3.10/site-packages/django/utils/functional.py", line 214, in inner
    return func(self._wrapped, *args)
AttributeError: 'User' object has no attribute 'password1'
"POST /donate HTTP/1.1" 500 27
Exception while resolving variable 'fname' in template 'authentication/user.html'.
Traceback (most recent call last):
  File "/Users/ughestaff/.local/share/virtualenvs/Codes-vPfYgZ7o/lib/python3.10/site-packages/django/template/base.py", line 829, in _resolve_lookup
    current = current[bit]
  File "/Users/ughestaff/.local/share/virtualenvs/Codes-vPfYgZ7o/lib/python3.10/site-packages/django/template/context.py", line 83, in __getitem__
    raise KeyError(key)
KeyError: 'fname'

During handling of the above exception, another exception occurred:

Traceback (most recent call last):
  File "/Users/ughestaff/.local/share/virtualenvs/Codes-vPfYgZ7o/lib/python3.10/site-packages/django/template/base.py", line 835, in _resolve_lookup
    if isinstance(current, BaseContext) and getattr(type(current), bit):
AttributeError: type object 'RequestContext' has no attribute 'fname'

During handling of the above exception, another exception occurred:

Traceback (most recent call last):
  File "/Users/ughestaff/.local/share/virtualenvs/Codes-vPfYgZ7o/lib/python3.10/site-packages/django/template/base.py", line 843, in _resolve_lookup
    current = current[int(bit)]
ValueError: invalid literal for int() with base 10: 'fname'

During handling of the above exception, another exception occurred:

Traceback (most recent call last):
  File "/Users/ughestaff/.local/share/virtualenvs/Codes-vPfYgZ7o/lib/python3.10/site-packages/django/template/base.py", line 848, in _resolve_lookup
    raise VariableDoesNotExist("Failed lookup for key "
django.template.base.VariableDoesNotExist: Failed lookup for key [fname] in [{'True': True, 'False': False, 'None': None}, {'csrf_token': <SimpleLazyObject: <function csrf.<locals>._get_val at 0x103503760>>, 'request': <WSGIRequest: POST '/donate'>, 'user': <SimpleLazyObject: <User: Lil>>, 'perms': <django.contrib.auth.context_processors.PermWrapper object at 0x10357d270>, 'messages': <django.contrib.messages.storage.fallback.FallbackStorage object at 0x1034b2320>, 'DEFAULT_MESSAGE_LEVELS': {'DEBUG': 10, 'INFO': 20, 'SUCCESS': 25, 'WARNING': 30, 'ERROR': 40}}, {}]
"POST /donate HTTP/1.1" 200 5342
"GET /static/css/main.css HTTP/1.1" 304 0
"GET /static/Images/Logo.jpeg HTTP/1.1" 304 0
"GET /static/Images/email-box.jpeg HTTP/1.1" 304 0
Not Found: /static/node_modules/bulma/bulma
"GET /static/node_modules/bulma/bulma HTTP/1.1" 404 105
"GET /static/Images/Background2.jpeg HTTP/1.1" 304 0
Exception while resolving variable 'errors' in template 'admin/change_list.html'.
Traceback (most recent call last):
  File "/Users/ughestaff/.local/share/virtualenvs/Codes-vPfYgZ7o/lib/python3.10/site-packages/django/template/base.py", line 829, in _resolve_lookup
    current = current[bit]
TypeError: 'NoneType' object is not subscriptable

During handling of the above exception, another exception occurred:

Traceback (most recent call last):
  File "/Users/ughestaff/.local/share/virtualenvs/Codes-vPfYgZ7o/lib/python3.10/site-packages/django/template/base.py", line 837, in _resolve_lookup
    current = getattr(current, bit)
AttributeError: 'NoneType' object has no attribute 'errors'

During handling of the above exception, another exception occurred:

Traceback (most recent call last):
  File "/Users/ughestaff/.local/share/virtualenvs/Codes-vPfYgZ7o/lib/python3.10/site-packages/django/template/base.py", line 843, in _resolve_lookup
    current = current[int(bit)]
ValueError: invalid literal for int() with base 10: 'errors'

During handling of the above exception, another exception occurred:

Traceback (most recent call last):
  File "/Users/ughestaff/.local/share/virtualenvs/Codes-vPfYgZ7o/lib/python3.10/site-packages/django/template/base.py", line 848, in _resolve_lookup
    raise VariableDoesNotExist("Failed lookup for key "
django.template.base.VariableDoesNotExist: Failed lookup for key [errors] in None
Exception while resolving variable 'show' in template 'admin/change_list.html'.
Traceback (most recent call last):
  File "/Users/ughestaff/.local/share/virtualenvs/Codes-vPfYgZ7o/lib/python3.10/site-packages/django/template/base.py", line 829, in _resolve_lookup
    current = current[bit]
  File "/Users/ughestaff/.local/share/virtualenvs/Codes-vPfYgZ7o/lib/python3.10/site-packages/django/template/context.py", line 83, in __getitem__
    raise KeyError(key)
KeyError: 'show'

During handling of the above exception, another exception occurred:

Traceback (most recent call last):
  File "/Users/ughestaff/.local/share/virtualenvs/Codes-vPfYgZ7o/lib/python3.10/site-packages/django/template/base.py", line 835, in _resolve_lookup
    if isinstance(current, BaseContext) and getattr(type(current), bit):
AttributeError: type object 'RequestContext' has no attribute 'show'

During handling of the above exception, another exception occurred:

Traceback (most recent call last):
  File "/Users/ughestaff/.local/share/virtualenvs/Codes-vPfYgZ7o/lib/python3.10/site-packages/django/template/base.py", line 843, in _resolve_lookup
    current = current[int(bit)]
ValueError: invalid literal for int() with base 10: 'show'

During handling of the above exception, another exception occurred:

Traceback (most recent call last):
  File "/Users/ughestaff/.local/share/virtualenvs/Codes-vPfYgZ7o/lib/python3.10/site-packages/django/template/base.py", line 848, in _resolve_lookup
    raise VariableDoesNotExist("Failed lookup for key "
django.template.base.VariableDoesNotExist: Failed lookup for key [show] in [{'True': True, 'False': False, 'None': None, 'csrf_token': <SimpleLazyObject: <function csrf.<locals>._get_val at 0x1035763b0>>}]
Exception while resolving variable 'is_multipart' in template 'admin/change_list.html'.
Traceback (most recent call last):
  File "/Users/ughestaff/.local/share/virtualenvs/Codes-vPfYgZ7o/lib/python3.10/site-packages/django/template/base.py", line 829, in _resolve_lookup
    current = current[bit]
TypeError: 'NoneType' object is not subscriptable

During handling of the above exception, another exception occurred:

Traceback (most recent call last):
  File "/Users/ughestaff/.local/share/virtualenvs/Codes-vPfYgZ7o/lib/python3.10/site-packages/django/template/base.py", line 837, in _resolve_lookup
    current = getattr(current, bit)
AttributeError: 'NoneType' object has no attribute 'is_multipart'

During handling of the above exception, another exception occurred:

Traceback (most recent call last):
  File "/Users/ughestaff/.local/share/virtualenvs/Codes-vPfYgZ7o/lib/python3.10/site-packages/django/template/base.py", line 843, in _resolve_lookup
    current = current[int(bit)]
ValueError: invalid literal for int() with base 10: 'is_multipart'

During handling of the above exception, another exception occurred:

Traceback (most recent call last):
  File "/Users/ughestaff/.local/share/virtualenvs/Codes-vPfYgZ7o/lib/python3.10/site-packages/django/template/base.py", line 848, in _resolve_lookup
    raise VariableDoesNotExist("Failed lookup for key "
django.template.base.VariableDoesNotExist: Failed lookup for key [is_multipart] in None
Exception while resolving variable 'non_field_errors' in template 'admin/change_list.html'.
Traceback (most recent call last):
  File "/Users/ughestaff/.local/share/virtualenvs/Codes-vPfYgZ7o/lib/python3.10/site-packages/django/template/base.py", line 829, in _resolve_lookup
    current = current[bit]
TypeError: 'NoneType' object is not subscriptable

During handling of the above exception, another exception occurred:

Traceback (most recent call last):
  File "/Users/ughestaff/.local/share/virtualenvs/Codes-vPfYgZ7o/lib/python3.10/site-packages/django/template/base.py", line 837, in _resolve_lookup
    current = getattr(current, bit)
AttributeError: 'NoneType' object has no attribute 'non_field_errors'

During handling of the above exception, another exception occurred:

Traceback (most recent call last):
  File "/Users/ughestaff/.local/share/virtualenvs/Codes-vPfYgZ7o/lib/python3.10/site-packages/django/template/base.py", line 843, in _resolve_lookup
    current = current[int(bit)]
ValueError: invalid literal for int() with base 10: 'non_field_errors'

During handling of the above exception, another exception occurred:

Traceback (most recent call last):
  File "/Users/ughestaff/.local/share/virtualenvs/Codes-vPfYgZ7o/lib/python3.10/site-packages/django/template/base.py", line 848, in _resolve_lookup
    raise VariableDoesNotExist("Failed lookup for key "
django.template.base.VariableDoesNotExist: Failed lookup for key [non_field_errors] in None
Exception while resolving variable 'non_field_errors' in template 'admin/change_list.html'.
Traceback (most recent call last):
  File "/Users/ughestaff/.local/share/virtualenvs/Codes-vPfYgZ7o/lib/python3.10/site-packages/django/template/base.py", line 829, in _resolve_lookup
    current = current[bit]
TypeError: 'NoneType' object is not subscriptable

During handling of the above exception, another exception occurred:

Traceback (most recent call last):
  File "/Users/ughestaff/.local/share/virtualenvs/Codes-vPfYgZ7o/lib/python3.10/site-packages/django/template/base.py", line 837, in _resolve_lookup
    current = getattr(current, bit)
AttributeError: 'NoneType' object has no attribute 'non_field_errors'

During handling of the above exception, another exception occurred:

Traceback (most recent call last):
  File "/Users/ughestaff/.local/share/virtualenvs/Codes-vPfYgZ7o/lib/python3.10/site-packages/django/template/base.py", line 843, in _resolve_lookup
    current = current[int(bit)]
ValueError: invalid literal for int() with base 10: 'non_field_errors'

During handling of the above exception, another exception occurred:

Traceback (most recent call last):
  File "/Users/ughestaff/.local/share/virtualenvs/Codes-vPfYgZ7o/lib/python3.10/site-packages/django/template/base.py", line 848, in _resolve_lookup
    raise VariableDoesNotExist("Failed lookup for key "
django.template.base.VariableDoesNotExist: Failed lookup for key [non_field_errors] in None
Exception while resolving variable 'non_field_errors' in template 'admin/change_list.html'.
Traceback (most recent call last):
  File "/Users/ughestaff/.local/share/virtualenvs/Codes-vPfYgZ7o/lib/python3.10/site-packages/django/template/base.py", line 829, in _resolve_lookup
    current = current[bit]
TypeError: 'NoneType' object is not subscriptable

During handling of the above exception, another exception occurred:

Traceback (most recent call last):
  File "/Users/ughestaff/.local/share/virtualenvs/Codes-vPfYgZ7o/lib/python3.10/site-packages/django/template/base.py", line 837, in _resolve_lookup
    current = getattr(current, bit)
AttributeError: 'NoneType' object has no attribute 'non_field_errors'

During handling of the above exception, another exception occurred:

Traceback (most recent call last):
  File "/Users/ughestaff/.local/share/virtualenvs/Codes-vPfYgZ7o/lib/python3.10/site-packages/django/template/base.py", line 843, in _resolve_lookup
    current = current[int(bit)]
ValueError: invalid literal for int() with base 10: 'non_field_errors'

During handling of the above exception, another exception occurred:

Traceback (most recent call last):
  File "/Users/ughestaff/.local/share/virtualenvs/Codes-vPfYgZ7o/lib/python3.10/site-packages/django/template/base.py", line 848, in _resolve_lookup
    raise VariableDoesNotExist("Failed lookup for key "
django.template.base.VariableDoesNotExist: Failed lookup for key [non_field_errors] in None
Exception while resolving variable 'non_field_errors' in template 'admin/change_list.html'.
Traceback (most recent call last):
  File "/Users/ughestaff/.local/share/virtualenvs/Codes-vPfYgZ7o/lib/python3.10/site-packages/django/template/base.py", line 829, in _resolve_lookup
    current = current[bit]
TypeError: 'NoneType' object is not subscriptable

During handling of the above exception, another exception occurred:

Traceback (most recent call last):
  File "/Users/ughestaff/.local/share/virtualenvs/Codes-vPfYgZ7o/lib/python3.10/site-packages/django/template/base.py", line 837, in _resolve_lookup
    current = getattr(current, bit)
AttributeError: 'NoneType' object has no attribute 'non_field_errors'

During handling of the above exception, another exception occurred:

Traceback (most recent call last):
  File "/Users/ughestaff/.local/share/virtualenvs/Codes-vPfYgZ7o/lib/python3.10/site-packages/django/template/base.py", line 843, in _resolve_lookup
    current = current[int(bit)]
ValueError: invalid literal for int() with base 10: 'non_field_errors'

During handling of the above exception, another exception occurred:

Traceback (most recent call last):
  File "/Users/ughestaff/.local/share/virtualenvs/Codes-vPfYgZ7o/lib/python3.10/site-packages/django/template/base.py", line 848, in _resolve_lookup
    raise VariableDoesNotExist("Failed lookup for key "
django.template.base.VariableDoesNotExist: Failed lookup for key [non_field_errors] in None
Exception while resolving variable 'non_field_errors' in template 'admin/change_list.html'.
Traceback (most recent call last):
  File "/Users/ughestaff/.local/share/virtualenvs/Codes-vPfYgZ7o/lib/python3.10/site-packages/django/template/base.py", line 829, in _resolve_lookup
    current = current[bit]
TypeError: 'NoneType' object is not subscriptable

During handling of the above exception, another exception occurred:

Traceback (most recent call last):
  File "/Users/ughestaff/.local/share/virtualenvs/Codes-vPfYgZ7o/lib/python3.10/site-packages/django/template/base.py", line 837, in _resolve_lookup
    current = getattr(current, bit)
AttributeError: 'NoneType' object has no attribute 'non_field_errors'

During handling of the above exception, another exception occurred:

Traceback (most recent call last):
  File "/Users/ughestaff/.local/share/virtualenvs/Codes-vPfYgZ7o/lib/python3.10/site-packages/django/template/base.py", line 843, in _resolve_lookup
    current = current[int(bit)]
ValueError: invalid literal for int() with base 10: 'non_field_errors'

During handling of the above exception, another exception occurred:

Traceback (most recent call last):
  File "/Users/ughestaff/.local/share/virtualenvs/Codes-vPfYgZ7o/lib/python3.10/site-packages/django/template/base.py", line 848, in _resolve_lookup
    raise VariableDoesNotExist("Failed lookup for key "
django.template.base.VariableDoesNotExist: Failed lookup for key [non_field_errors] in None
Exception while resolving variable 'non_field_errors' in template 'admin/change_list.html'.
Traceback (most recent call last):
  File "/Users/ughestaff/.local/share/virtualenvs/Codes-vPfYgZ7o/lib/python3.10/site-packages/django/template/base.py", line 829, in _resolve_lookup
    current = current[bit]
TypeError: 'NoneType' object is not subscriptable

During handling of the above exception, another exception occurred:

Traceback (most recent call last):
  File "/Users/ughestaff/.local/share/virtualenvs/Codes-vPfYgZ7o/lib/python3.10/site-packages/django/template/base.py", line 837, in _resolve_lookup
    current = getattr(current, bit)
AttributeError: 'NoneType' object has no attribute 'non_field_errors'

During handling of the above exception, another exception occurred:

Traceback (most recent call last):
  File "/Users/ughestaff/.local/share/virtualenvs/Codes-vPfYgZ7o/lib/python3.10/site-packages/django/template/base.py", line 843, in _resolve_lookup
    current = current[int(bit)]
ValueError: invalid literal for int() with base 10: 'non_field_errors'

During handling of the above exception, another exception occurred:

Traceback (most recent call last):
  File "/Users/ughestaff/.local/share/virtualenvs/Codes-vPfYgZ7o/lib/python3.10/site-packages/django/template/base.py", line 848, in _resolve_lookup
    raise VariableDoesNotExist("Failed lookup for key "
django.template.base.VariableDoesNotExist: Failed lookup for key [non_field_errors] in None
Exception while resolving variable 'non_field_errors' in template 'admin/change_list.html'.
Traceback (most recent call last):
  File "/Users/ughestaff/.local/share/virtualenvs/Codes-vPfYgZ7o/lib/python3.10/site-packages/django/template/base.py", line 829, in _resolve_lookup
    current = current[bit]
TypeError: 'NoneType' object is not subscriptable

During handling of the above exception, another exception occurred:

Traceback (most recent call last):
  File "/Users/ughestaff/.local/share/virtualenvs/Codes-vPfYgZ7o/lib/python3.10/site-packages/django/template/base.py", line 837, in _resolve_lookup
    current = getattr(current, bit)
AttributeError: 'NoneType' object has no attribute 'non_field_errors'

During handling of the above exception, another exception occurred:

Traceback (most recent call last):
  File "/Users/ughestaff/.local/share/virtualenvs/Codes-vPfYgZ7o/lib/python3.10/site-packages/django/template/base.py", line 843, in _resolve_lookup
    current = current[int(bit)]
ValueError: invalid literal for int() with base 10: 'non_field_errors'

During handling of the above exception, another exception occurred:

Traceback (most recent call last):
  File "/Users/ughestaff/.local/share/virtualenvs/Codes-vPfYgZ7o/lib/python3.10/site-packages/django/template/base.py", line 848, in _resolve_lookup
    raise VariableDoesNotExist("Failed lookup for key "
django.template.base.VariableDoesNotExist: Failed lookup for key [non_field_errors] in None
Exception while resolving variable 'non_field_errors' in template 'admin/change_list.html'.
Traceback (most recent call last):
  File "/Users/ughestaff/.local/share/virtualenvs/Codes-vPfYgZ7o/lib/python3.10/site-packages/django/template/base.py", line 829, in _resolve_lookup
    current = current[bit]
TypeError: 'NoneType' object is not subscriptable

During handling of the above exception, another exception occurred:

Traceback (most recent call last):
  File "/Users/ughestaff/.local/share/virtualenvs/Codes-vPfYgZ7o/lib/python3.10/site-packages/django/template/base.py", line 837, in _resolve_lookup
    current = getattr(current, bit)
AttributeError: 'NoneType' object has no attribute 'non_field_errors'

During handling of the above exception, another exception occurred:

Traceback (most recent call last):
  File "/Users/ughestaff/.local/share/virtualenvs/Codes-vPfYgZ7o/lib/python3.10/site-packages/django/template/base.py", line 843, in _resolve_lookup
    current = current[int(bit)]
ValueError: invalid literal for int() with base 10: 'non_field_errors'

During handling of the above exception, another exception occurred:

Traceback (most recent call last):
  File "/Users/ughestaff/.local/share/virtualenvs/Codes-vPfYgZ7o/lib/python3.10/site-packages/django/template/base.py", line 848, in _resolve_lookup
    raise VariableDoesNotExist("Failed lookup for key "
django.template.base.VariableDoesNotExist: Failed lookup for key [non_field_errors] in None
Exception while resolving variable 'non_field_errors' in template 'admin/change_list.html'.
Traceback (most recent call last):
  File "/Users/ughestaff/.local/share/virtualenvs/Codes-vPfYgZ7o/lib/python3.10/site-packages/django/template/base.py", line 829, in _resolve_lookup
    current = current[bit]
TypeError: 'NoneType' object is not subscriptable

During handling of the above exception, another exception occurred:

Traceback (most recent call last):
  File "/Users/ughestaff/.local/share/virtualenvs/Codes-vPfYgZ7o/lib/python3.10/site-packages/django/template/base.py", line 837, in _resolve_lookup
    current = getattr(current, bit)
AttributeError: 'NoneType' object has no attribute 'non_field_errors'

During handling of the above exception, another exception occurred:

Traceback (most recent call last):
  File "/Users/ughestaff/.local/share/virtualenvs/Codes-vPfYgZ7o/lib/python3.10/site-packages/django/template/base.py", line 843, in _resolve_lookup
    current = current[int(bit)]
ValueError: invalid literal for int() with base 10: 'non_field_errors'

During handling of the above exception, another exception occurred:

Traceback (most recent call last):
  File "/Users/ughestaff/.local/share/virtualenvs/Codes-vPfYgZ7o/lib/python3.10/site-packages/django/template/base.py", line 848, in _resolve_lookup
    raise VariableDoesNotExist("Failed lookup for key "
django.template.base.VariableDoesNotExist: Failed lookup for key [non_field_errors] in None
Exception while resolving variable 'non_field_errors' in template 'admin/change_list.html'.
Traceback (most recent call last):
  File "/Users/ughestaff/.local/share/virtualenvs/Codes-vPfYgZ7o/lib/python3.10/site-packages/django/template/base.py", line 829, in _resolve_lookup
    current = current[bit]
TypeError: 'NoneType' object is not subscriptable

During handling of the above exception, another exception occurred:

Traceback (most recent call last):
  File "/Users/ughestaff/.local/share/virtualenvs/Codes-vPfYgZ7o/lib/python3.10/site-packages/django/template/base.py", line 837, in _resolve_lookup
    current = getattr(current, bit)
AttributeError: 'NoneType' object has no attribute 'non_field_errors'

During handling of the above exception, another exception occurred:

Traceback (most recent call last):
  File "/Users/ughestaff/.local/share/virtualenvs/Codes-vPfYgZ7o/lib/python3.10/site-packages/django/template/base.py", line 843, in _resolve_lookup
    current = current[int(bit)]
ValueError: invalid literal for int() with base 10: 'non_field_errors'

During handling of the above exception, another exception occurred:

Traceback (most recent call last):
  File "/Users/ughestaff/.local/share/virtualenvs/Codes-vPfYgZ7o/lib/python3.10/site-packages/django/template/base.py", line 848, in _resolve_lookup
    raise VariableDoesNotExist("Failed lookup for key "
django.template.base.VariableDoesNotExist: Failed lookup for key [non_field_errors] in None
"GET /admin/donate/donor/ HTTP/1.1" 200 6295
"GET /admin/donate/donor/11/change/ HTTP/1.1" 200 8259
"GET /admin/jsi18n/ HTTP/1.1" 200 3185
"GET /static/admin/js/vendor/jquery/jquery.min.js HTTP/1.1" 304 0
"GET /static/admin/css/base.css HTTP/1.1" 200 16225
"GET /static/admin/js/admin/RelatedObjectLookups.js HTTP/1.1" 304 0
"GET /static/admin/js/core.js HTTP/1.1" 304 0
"GET /static/admin/js/actions.min.js HTTP/1.1" 304 0
"GET /static/admin/js/prepopulate.min.js HTTP/1.1" 304 0
"GET /static/admin/js/vendor/xregexp/xregexp.min.js HTTP/1.1" 304 0
"GET /static/admin/js/urlify.js HTTP/1.1" 304 0
"GET /static/admin/js/calendar.js HTTP/1.1" 304 0
"GET /static/admin/js/admin/DateTimeShortcuts.js HTTP/1.1" 304 0
"GET / HTTP/1.1" 200 2443
"GET /static/css/main.css HTTP/1.1" 304 0
"GET /static/Images/Logo.jpeg HTTP/1.1" 304 0
Not Found: /static/node_modules/bulma/bulma
"GET /static/node_modules/bulma/bulma HTTP/1.1" 404 105
"GET /static/Images/Background2.jpeg HTTP/1.1" 304 0
Not Found: /favicon.ico
"GET /favicon.ico HTTP/1.1" 404 85
"GET / HTTP/1.1" 200 2443
"GET /static/css/main.css HTTP/1.1" 304 0
"GET /static/Images/Logo.jpeg HTTP/1.1" 304 0
Not Found: /static/node_modules/bulma/bulma
"GET /static/node_modules/bulma/bulma HTTP/1.1" 404 105
"GET /static/Images/Background2.jpeg HTTP/1.1" 304 0
"GET / HTTP/1.1" 200 2443
Not Found: /static/node_modules/bulma/bulma
"GET /static/node_modules/bulma/bulma HTTP/1.1" 404 105
"GET / HTTP/1.1" 200 2443
Not Found: /static/node_modules/bulma/bulma
"GET /static/node_modules/bulma/bulma HTTP/1.1" 404 105
"GET /home HTTP/1.1" 200 2443
Not Found: /static/node_modules/bulma/bulma
"GET /static/node_modules/bulma/bulma HTTP/1.1" 404 105
"GET /home HTTP/1.1" 200 2443
Not Found: /static/node_modules/bulma/bulma
"GET /static/node_modules/bulma/bulma HTTP/1.1" 404 105
"GET /signin HTTP/1.1" 200 3345
Not Found: /static/node_modules/bulma/bulma
"GET /static/node_modules/bulma/bulma HTTP/1.1" 404 105
"POST /signin_user HTTP/1.1" 200 5349
"GET /static/Images/email-box.jpeg HTTP/1.1" 304 0
Not Found: /static/node_modules/bulma/bulma
"GET /static/node_modules/bulma/bulma HTTP/1.1" 404 105
"GET / HTTP/1.1" 200 2443
Not Found: /static/node_modules/bulma/bulma
"GET /static/node_modules/bulma/bulma HTTP/1.1" 404 105
"GET / HTTP/1.1" 200 2443
"GET /static/css/main.css HTTP/1.1" 304 0
"GET /static/Images/Logo.jpeg HTTP/1.1" 304 0
Not Found: /static/node_modules/bulma/bulma
"GET /static/node_modules/bulma/bulma HTTP/1.1" 404 105
"GET /static/Images/Background2.jpeg HTTP/1.1" 304 0
"GET /signout HTTP/1.1" 302 0
"GET / HTTP/1.1" 200 8958
"GET /static/Images/Head_Picture.png HTTP/1.1" 304 0
"GET /static/Images/img-howitworks-2.jpeg HTTP/1.1" 304 0
"GET /static/Images/email-box.jpeg HTTP/1.1" 304 0
Not Found: /static/node_modules/bulma/bulma
"GET /static/node_modules/bulma/bulma HTTP/1.1" 404 105
"GET /signin HTTP/1.1" 200 3345
Not Found: /static/node_modules/bulma/bulma
"GET /static/node_modules/bulma/bulma HTTP/1.1" 404 105
"POST /signin_user HTTP/1.1" 200 5349
"GET /static/css/main.css HTTP/1.1" 304 0
"GET /static/Images/Logo.jpeg HTTP/1.1" 304 0
"GET /static/Images/email-box.jpeg HTTP/1.1" 304 0
Not Found: /static/node_modules/bulma/bulma
"GET /static/node_modules/bulma/bulma HTTP/1.1" 404 105
"GET /static/Images/Background2.jpeg HTTP/1.1" 304 0
"GET /signout HTTP/1.1" 302 0
Internal Server Error: /
Traceback (most recent call last):
  File "/Users/ughestaff/.local/share/virtualenvs/Codes-vPfYgZ7o/lib/python3.10/site-packages/django/core/handlers/exception.py", line 34, in inner
    response = get_response(request)
  File "/Users/ughestaff/.local/share/virtualenvs/Codes-vPfYgZ7o/lib/python3.10/site-packages/django/core/handlers/base.py", line 126, in _get_response
    response = self.process_exception_by_middleware(e, request)
  File "/Users/ughestaff/.local/share/virtualenvs/Codes-vPfYgZ7o/lib/python3.10/site-packages/django/core/handlers/base.py", line 124, in _get_response
    response = wrapped_callback(request, *callback_args, **callback_kwargs)
  File "/Users/ughestaff/OneDrive - IU International University of Applied Sciences/School/Subjects/In Progress/Project Software Engineering/BloodLoof/2. Development Phase/Codes/authentication/views.py", line 16, in home
    return render(request, "authentication/homepage.html")
  File "/Users/ughestaff/.local/share/virtualenvs/Codes-vPfYgZ7o/lib/python3.10/site-packages/django/shortcuts.py", line 36, in render
    content = loader.render_to_string(template_name, context, request, using=using)
  File "/Users/ughestaff/.local/share/virtualenvs/Codes-vPfYgZ7o/lib/python3.10/site-packages/django/template/loader.py", line 61, in render_to_string
    template = get_template(template_name, using=using)
  File "/Users/ughestaff/.local/share/virtualenvs/Codes-vPfYgZ7o/lib/python3.10/site-packages/django/template/loader.py", line 15, in get_template
    return engine.get_template(template_name)
  File "/Users/ughestaff/.local/share/virtualenvs/Codes-vPfYgZ7o/lib/python3.10/site-packages/django/template/backends/django.py", line 34, in get_template
    return Template(self.engine.get_template(template_name), self)
  File "/Users/ughestaff/.local/share/virtualenvs/Codes-vPfYgZ7o/lib/python3.10/site-packages/django/template/engine.py", line 144, in get_template
    template, origin = self.find_template(template_name)
  File "/Users/ughestaff/.local/share/virtualenvs/Codes-vPfYgZ7o/lib/python3.10/site-packages/django/template/engine.py", line 126, in find_template
    template = loader.get_template(name, skip=skip)
  File "/Users/ughestaff/.local/share/virtualenvs/Codes-vPfYgZ7o/lib/python3.10/site-packages/django/template/loaders/cached.py", line 54, in get_template
    template = super().get_template(template_name, skip)
  File "/Users/ughestaff/.local/share/virtualenvs/Codes-vPfYgZ7o/lib/python3.10/site-packages/django/template/loaders/base.py", line 29, in get_template
    return Template(
  File "/Users/ughestaff/.local/share/virtualenvs/Codes-vPfYgZ7o/lib/python3.10/site-packages/django/template/base.py", line 156, in __init__
    self.nodelist = self.compile_nodelist()
  File "/Users/ughestaff/.local/share/virtualenvs/Codes-vPfYgZ7o/lib/python3.10/site-packages/django/template/base.py", line 194, in compile_nodelist
    return parser.parse()
  File "/Users/ughestaff/.local/share/virtualenvs/Codes-vPfYgZ7o/lib/python3.10/site-packages/django/template/base.py", line 478, in parse
    raise self.error(token, e)
  File "/Users/ughestaff/.local/share/virtualenvs/Codes-vPfYgZ7o/lib/python3.10/site-packages/django/template/base.py", line 476, in parse
    compiled_result = compile_func(self, token)
  File "/Users/ughestaff/.local/share/virtualenvs/Codes-vPfYgZ7o/lib/python3.10/site-packages/django/template/defaulttags.py", line 951, in do_if
    nodelist = parser.parse(('elif', 'else', 'endif'))
  File "/Users/ughestaff/.local/share/virtualenvs/Codes-vPfYgZ7o/lib/python3.10/site-packages/django/template/base.py", line 483, in parse
    self.unclosed_block_tag(parse_until)
  File "/Users/ughestaff/.local/share/virtualenvs/Codes-vPfYgZ7o/lib/python3.10/site-packages/django/template/base.py", line 544, in unclosed_block_tag
    raise self.error(token, msg)
django.template.exceptions.TemplateSyntaxError: Unclosed tag on line 50: 'if'. Looking for one of: elif, else, endif.
"GET / HTTP/1.1" 500 27
Forbidden (CSRF token missing or incorrect.): /signin_user
"POST /signin_user HTTP/1.1" 403 1019
Forbidden (CSRF token missing or incorrect.): /signin_user
"POST /signin_user HTTP/1.1" 403 1019
"GET / HTTP/1.1" 200 9236
"GET /static/css/main.css HTTP/1.1" 304 0
"GET /static/Images/Logo.jpeg HTTP/1.1" 304 0
"GET /static/Images/Head_Picture.png HTTP/1.1" 304 0
"GET /static/Images/img-howitworks-2.jpeg HTTP/1.1" 304 0
"GET /static/Images/email-box.jpeg HTTP/1.1" 304 0
"GET / HTTP/1.1" 200 8906
"GET /static/Images/Logo.jpeg HTTP/1.1" 304 0
Not Found: /static/node_modules/bulma/bulma
"GET /static/node_modules/bulma/bulma HTTP/1.1" 404 105
"GET /static/Images/Background2.jpeg HTTP/1.1" 304 0
"GET /signin HTTP/1.1" 200 3345
Not Found: /static/node_modules/bulma/bulma
"GET /static/node_modules/bulma/bulma HTTP/1.1" 404 105
"POST /signin_user HTTP/1.1" 200 5349
Not Found: /static/node_modules/bulma/bulma
"GET /static/node_modules/bulma/bulma HTTP/1.1" 404 105
"GET /signout HTTP/1.1" 302 0
"GET / HTTP/1.1" 200 9236
Not Found: /static/node_modules/bulma/bulma
"GET /static/node_modules/bulma/bulma HTTP/1.1" 404 105
"GET / HTTP/1.1" 200 8906
Not Found: /static/node_modules/bulma/bulma
"GET /static/node_modules/bulma/bulma HTTP/1.1" 404 105
ALTER TABLE "donate_donor" RENAME TO "donate_donor__old"; (params ())
CREATE TABLE "donate_donor" ("id" integer NOT NULL PRIMARY KEY AUTOINCREMENT, "password" varchar(128) NOT NULL, "last_login" datetime NULL, "phone_number" varchar(14) NULL, "dob" date NULL, "weight" decimal NULL, "height" decimal NULL, "available_time" datetime NULL, "username" varchar(14) NULL, "hospital" varchar(14) NULL); (params None)
INSERT INTO "donate_donor" ("id", "password", "last_login", "phone_number", "dob", "weight", "height", "available_time", "username", "hospital") SELECT "id", "password", "last_login", "phone_number", "dob", "weight", "height", "available_time", "username", NULL FROM "donate_donor__old"; (params ())
DROP TABLE "donate_donor__old"; (params ())
"GET /signin HTTP/1.1" 200 3345
"GET /static/css/main.css HTTP/1.1" 304 0
"GET /static/Images/Logo.jpeg HTTP/1.1" 304 0
Not Found: /static/node_modules/bulma/bulma
"GET /static/node_modules/bulma/bulma HTTP/1.1" 404 105
"GET /static/Images/Background2.jpeg HTTP/1.1" 304 0
"POST /signin_user HTTP/1.1" 200 5349
"GET /static/Images/email-box.jpeg HTTP/1.1" 304 0
Not Found: /static/node_modules/bulma/bulma
"GET /static/node_modules/bulma/bulma HTTP/1.1" 404 105
"GET /donate HTTP/1.1" 200 4910
Not Found: /static/node_modules/bulma/bulma
"GET /static/node_modules/bulma/bulma HTTP/1.1" 404 105
"GET /donate HTTP/1.1" 200 4910
"GET /static/css/main.css HTTP/1.1" 304 0
Not Found: /static/node_modules/bulma/bulma
"GET /static/node_modules/bulma/bulma HTTP/1.1" 404 105
"GET /donate HTTP/1.1" 200 4910
Not Found: /static/node_modules/bulma/bulma
"GET /static/node_modules/bulma/bulma HTTP/1.1" 404 105
"GET / HTTP/1.1" 200 2554
"GET /static/Images/Logo.jpeg HTTP/1.1" 304 0
"GET /static/Images/Logo.jpeg HTTP/1.1" 304 0
Not Found: /static/node_modules/bulma/bulma
"GET /static/node_modules/bulma/bulma HTTP/1.1" 404 105
"GET /static/Images/Background2.jpeg HTTP/1.1" 304 0
"GET /signin_user HTTP/1.1" 200 3345
Not Found: /static/node_modules/bulma/bulma
"GET /static/node_modules/bulma/bulma HTTP/1.1" 404 105
"POST /signin_user HTTP/1.1" 200 5349
"GET /static/Images/email-box.jpeg HTTP/1.1" 304 0
Not Found: /static/node_modules/bulma/bulma
"GET /static/node_modules/bulma/bulma HTTP/1.1" 404 105
"GET /donate HTTP/1.1" 200 4919
Not Found: /static/node_modules/bulma/bulma
"GET /static/node_modules/bulma/bulma HTTP/1.1" 404 105
"GET /signin_user HTTP/1.1" 200 3345
"POST /signin_user HTTP/1.1" 200 5349
"GET /static/css/main.css HTTP/1.1" 304 0
"GET /static/Images/Logo.jpeg HTTP/1.1" 304 0
"GET /static/Images/email-box.jpeg HTTP/1.1" 304 0
Not Found: /static/node_modules/bulma/bulma
"GET /static/node_modules/bulma/bulma HTTP/1.1" 404 105
"GET /static/Images/Background2.jpeg HTTP/1.1" 304 0
"GET /donate HTTP/1.1" 200 4919
Not Found: /static/node_modules/bulma/bulma
"GET /static/node_modules/bulma/bulma HTTP/1.1" 404 105
"GET / HTTP/1.1" 200 2554
"GET /static/css/main.css HTTP/1.1" 304 0
"GET /static/Images/Logo.jpeg HTTP/1.1" 304 0
Not Found: /static/node_modules/bulma/bulma
"GET /static/node_modules/bulma/bulma HTTP/1.1" 404 105
"GET /static/Images/Background2.jpeg HTTP/1.1" 304 0
"GET /signin_user HTTP/1.1" 200 3345
Not Found: /static/node_modules/bulma/bulma
"GET /static/node_modules/bulma/bulma HTTP/1.1" 404 105
"POST /signin_user HTTP/1.1" 200 5349
"GET /static/Images/email-box.jpeg HTTP/1.1" 304 0
Not Found: /static/node_modules/bulma/bulma
"GET /static/node_modules/bulma/bulma HTTP/1.1" 404 105
"GET /donate HTTP/1.1" 200 4484
Not Found: /static/node_modules/bulma/bulma
"GET /static/node_modules/bulma/bulma HTTP/1.1" 404 105
"GET /donate HTTP/1.1" 200 4478
Not Found: /static/node_modules/bulma/bulma
"GET /static/node_modules/bulma/bulma HTTP/1.1" 404 105
"GET /donate HTTP/1.1" 200 4478
"GET /static/css/main.css HTTP/1.1" 304 0
Not Found: /static/node_modules/bulma/bulma
"GET /static/node_modules/bulma/bulma HTTP/1.1" 404 105
"GET /donate HTTP/1.1" 200 4478
Not Found: /static/node_modules/bulma/bulma
"GET /static/node_modules/bulma/bulma HTTP/1.1" 404 105
"GET /donate HTTP/1.1" 200 4441
Not Found: /static/node_modules/bulma/bulma
"GET /static/node_modules/bulma/bulma HTTP/1.1" 404 105
"GET /donate HTTP/1.1" 200 4441
Not Found: /static/node_modules/bulma/bulma
"GET /static/node_modules/bulma/bulma HTTP/1.1" 404 105
"GET /donate HTTP/1.1" 200 4560
"GET /static/css/main.css HTTP/1.1" 304 0
Not Found: /static/node_modules/bulma/bulma
"GET /static/node_modules/bulma/bulma HTTP/1.1" 404 105
ALTER TABLE "donate_donor" RENAME TO "donate_donor__old"; (params ())
CREATE TABLE "donate_donor" ("id" integer NOT NULL PRIMARY KEY AUTOINCREMENT, "password" varchar(128) NOT NULL, "last_login" datetime NULL, "phone_number" varchar(14) NULL, "dob" date NULL, "weight" decimal NULL, "height" decimal NULL, "available_time" datetime NULL, "username" varchar(14) NULL, "hospital" varchar(14) NULL, "address" varchar(14) NULL); (params None)
INSERT INTO "donate_donor" ("id", "password", "last_login", "phone_number", "dob", "weight", "height", "available_time", "username", "hospital", "address") SELECT "id", "password", "last_login", "phone_number", "dob", "weight", "height", "available_time", "username", "hospital", NULL FROM "donate_donor__old"; (params ())
DROP TABLE "donate_donor__old"; (params ())
"GET /donate HTTP/1.1" 200 3919
"GET /static/css/main.css HTTP/1.1" 304 0
Not Found: /static/node_modules/bulma/bulma
"GET /static/node_modules/bulma/bulma HTTP/1.1" 404 105
Exception while resolving variable 'is_popup' in template 'admin/index.html'.
Traceback (most recent call last):
  File "/Users/ughestaff/.local/share/virtualenvs/Codes-vPfYgZ7o/lib/python3.10/site-packages/django/template/base.py", line 829, in _resolve_lookup
    current = current[bit]
  File "/Users/ughestaff/.local/share/virtualenvs/Codes-vPfYgZ7o/lib/python3.10/site-packages/django/template/context.py", line 83, in __getitem__
    raise KeyError(key)
KeyError: 'is_popup'

During handling of the above exception, another exception occurred:

Traceback (most recent call last):
  File "/Users/ughestaff/.local/share/virtualenvs/Codes-vPfYgZ7o/lib/python3.10/site-packages/django/template/base.py", line 835, in _resolve_lookup
    if isinstance(current, BaseContext) and getattr(type(current), bit):
AttributeError: type object 'RequestContext' has no attribute 'is_popup'

During handling of the above exception, another exception occurred:

Traceback (most recent call last):
  File "/Users/ughestaff/.local/share/virtualenvs/Codes-vPfYgZ7o/lib/python3.10/site-packages/django/template/base.py", line 843, in _resolve_lookup
    current = current[int(bit)]
ValueError: invalid literal for int() with base 10: 'is_popup'

During handling of the above exception, another exception occurred:

Traceback (most recent call last):
  File "/Users/ughestaff/.local/share/virtualenvs/Codes-vPfYgZ7o/lib/python3.10/site-packages/django/template/base.py", line 848, in _resolve_lookup
    raise VariableDoesNotExist("Failed lookup for key "
django.template.base.VariableDoesNotExist: Failed lookup for key [is_popup] in [{'True': True, 'False': False, 'None': None}, {'csrf_token': <SimpleLazyObject: <function csrf.<locals>._get_val at 0x104da9d80>>, 'request': <WSGIRequest: GET '/admin/'>, 'user': <SimpleLazyObject: <User: myadmin>>, 'perms': <django.contrib.auth.context_processors.PermWrapper object at 0x104e305b0>, 'messages': <django.contrib.messages.storage.fallback.FallbackStorage object at 0x104d53d90>, 'DEFAULT_MESSAGE_LEVELS': {'DEBUG': 10, 'INFO': 20, 'SUCCESS': 25, 'WARNING': 30, 'ERROR': 40}}, {}, {'site_title': 'Django site admin', 'site_header': 'Django administration', 'site_url': '/', 'has_permission': True, 'available_apps': [{'name': 'Authentication and Authorization', 'app_label': 'auth', 'app_url': '/admin/auth/', 'has_module_perms': True, 'models': [{'name': 'Groups', 'object_name': 'Group', 'perms': {'add': True, 'change': True, 'delete': True, 'view': True}, 'view_only': False, 'admin_url': '/admin/auth/group/', 'add_url': '/admin/auth/group/add/'}, {'name': 'Users', 'object_name': 'User', 'perms': {'add': True, 'change': True, 'delete': True, 'view': True}, 'view_only': False, 'admin_url': '/admin/auth/user/', 'add_url': '/admin/auth/user/add/'}]}, {'name': 'Donate', 'app_label': 'donate', 'app_url': '/admin/donate/', 'has_module_perms': True, 'models': [{'name': 'Donors', 'object_name': 'Donor', 'perms': {'add': True, 'change': True, 'delete': True, 'view': True}, 'view_only': False, 'admin_url': '/admin/donate/donor/', 'add_url': '/admin/donate/donor/add/'}]}], 'title': 'Site administration', 'app_list': [{'name': 'Authentication and Authorization', 'app_label': 'auth', 'app_url': '/admin/auth/', 'has_module_perms': True, 'models': [{'name': 'Groups', 'object_name': 'Group', 'perms': {'add': True, 'change': True, 'delete': True, 'view': True}, 'view_only': False, 'admin_url': '/admin/auth/group/', 'add_url': '/admin/auth/group/add/'}, {'name': 'Users', 'object_name': 'User', 'perms': {'add': True, 'change': True, 'delete': True, 'view': True}, 'view_only': False, 'admin_url': '/admin/auth/user/', 'add_url': '/admin/auth/user/add/'}]}, {'name': 'Donate', 'app_label': 'donate', 'app_url': '/admin/donate/', 'has_module_perms': True, 'models': [{'name': 'Donors', 'object_name': 'Donor', 'perms': {'add': True, 'change': True, 'delete': True, 'view': True}, 'view_only': False, 'admin_url': '/admin/donate/donor/', 'add_url': '/admin/donate/donor/add/'}]}], 'LANGUAGE_CODE': 'en-us', 'LANGUAGE_BIDI': False}]
Exception while resolving variable 'is_popup' in template 'admin/index.html'.
Traceback (most recent call last):
  File "/Users/ughestaff/.local/share/virtualenvs/Codes-vPfYgZ7o/lib/python3.10/site-packages/django/template/base.py", line 829, in _resolve_lookup
    current = current[bit]
  File "/Users/ughestaff/.local/share/virtualenvs/Codes-vPfYgZ7o/lib/python3.10/site-packages/django/template/context.py", line 83, in __getitem__
    raise KeyError(key)
KeyError: 'is_popup'

During handling of the above exception, another exception occurred:

Traceback (most recent call last):
  File "/Users/ughestaff/.local/share/virtualenvs/Codes-vPfYgZ7o/lib/python3.10/site-packages/django/template/base.py", line 835, in _resolve_lookup
    if isinstance(current, BaseContext) and getattr(type(current), bit):
AttributeError: type object 'RequestContext' has no attribute 'is_popup'

During handling of the above exception, another exception occurred:

Traceback (most recent call last):
  File "/Users/ughestaff/.local/share/virtualenvs/Codes-vPfYgZ7o/lib/python3.10/site-packages/django/template/base.py", line 843, in _resolve_lookup
    current = current[int(bit)]
ValueError: invalid literal for int() with base 10: 'is_popup'

During handling of the above exception, another exception occurred:

Traceback (most recent call last):
  File "/Users/ughestaff/.local/share/virtualenvs/Codes-vPfYgZ7o/lib/python3.10/site-packages/django/template/base.py", line 848, in _resolve_lookup
    raise VariableDoesNotExist("Failed lookup for key "
django.template.base.VariableDoesNotExist: Failed lookup for key [is_popup] in [{'True': True, 'False': False, 'None': None}, {'csrf_token': <SimpleLazyObject: <function csrf.<locals>._get_val at 0x104da9d80>>, 'request': <WSGIRequest: GET '/admin/'>, 'user': <SimpleLazyObject: <User: myadmin>>, 'perms': <django.contrib.auth.context_processors.PermWrapper object at 0x104e305b0>, 'messages': <django.contrib.messages.storage.fallback.FallbackStorage object at 0x104d53d90>, 'DEFAULT_MESSAGE_LEVELS': {'DEBUG': 10, 'INFO': 20, 'SUCCESS': 25, 'WARNING': 30, 'ERROR': 40}}, {}, {'site_title': 'Django site admin', 'site_header': 'Django administration', 'site_url': '/', 'has_permission': True, 'available_apps': [{'name': 'Authentication and Authorization', 'app_label': 'auth', 'app_url': '/admin/auth/', 'has_module_perms': True, 'models': [{'name': 'Groups', 'object_name': 'Group', 'perms': {'add': True, 'change': True, 'delete': True, 'view': True}, 'view_only': False, 'admin_url': '/admin/auth/group/', 'add_url': '/admin/auth/group/add/'}, {'name': 'Users', 'object_name': 'User', 'perms': {'add': True, 'change': True, 'delete': True, 'view': True}, 'view_only': False, 'admin_url': '/admin/auth/user/', 'add_url': '/admin/auth/user/add/'}]}, {'name': 'Donate', 'app_label': 'donate', 'app_url': '/admin/donate/', 'has_module_perms': True, 'models': [{'name': 'Donors', 'object_name': 'Donor', 'perms': {'add': True, 'change': True, 'delete': True, 'view': True}, 'view_only': False, 'admin_url': '/admin/donate/donor/', 'add_url': '/admin/donate/donor/add/'}]}], 'title': 'Site administration', 'app_list': [{'name': 'Authentication and Authorization', 'app_label': 'auth', 'app_url': '/admin/auth/', 'has_module_perms': True, 'models': [{'name': 'Groups', 'object_name': 'Group', 'perms': {'add': True, 'change': True, 'delete': True, 'view': True}, 'view_only': False, 'admin_url': '/admin/auth/group/', 'add_url': '/admin/auth/group/add/'}, {'name': 'Users', 'object_name': 'User', 'perms': {'add': True, 'change': True, 'delete': True, 'view': True}, 'view_only': False, 'admin_url': '/admin/auth/user/', 'add_url': '/admin/auth/user/add/'}]}, {'name': 'Donate', 'app_label': 'donate', 'app_url': '/admin/donate/', 'has_module_perms': True, 'models': [{'name': 'Donors', 'object_name': 'Donor', 'perms': {'add': True, 'change': True, 'delete': True, 'view': True}, 'view_only': False, 'admin_url': '/admin/donate/donor/', 'add_url': '/admin/donate/donor/add/'}]}], 'LANGUAGE_CODE': 'en-us', 'LANGUAGE_BIDI': False}]
"GET /admin/ HTTP/1.1" 200 4834
"GET /static/admin/css/base.css HTTP/1.1" 304 0
"GET /static/admin/css/dashboard.css HTTP/1.1" 304 0
"GET /static/admin/css/responsive.css HTTP/1.1" 304 0
Not Found: /favicon.ico
"GET /static/admin/css/fonts.css HTTP/1.1" 200 423
"GET /static/admin/img/icon-deletelink.svg HTTP/1.1" 200 392
"GET /static/admin/img/icon-changelink.svg HTTP/1.1" 200 380
"GET /static/admin/img/icon-addlink.svg HTTP/1.1" 200 331
"GET /static/admin/fonts/Roboto-Regular-webfont.woff HTTP/1.1" 304 0
"GET /static/admin/fonts/Roboto-Light-webfont.woff HTTP/1.1" 304 0
"GET /static/admin/fonts/Roboto-Bold-webfont.woff HTTP/1.1" 304 0
Exception while resolving variable 'errors' in template 'admin/change_list.html'.
Traceback (most recent call last):
  File "/Users/ughestaff/.local/share/virtualenvs/Codes-vPfYgZ7o/lib/python3.10/site-packages/django/template/base.py", line 829, in _resolve_lookup
    current = current[bit]
TypeError: 'NoneType' object is not subscriptable

During handling of the above exception, another exception occurred:

Traceback (most recent call last):
  File "/Users/ughestaff/.local/share/virtualenvs/Codes-vPfYgZ7o/lib/python3.10/site-packages/django/template/base.py", line 837, in _resolve_lookup
    current = getattr(current, bit)
AttributeError: 'NoneType' object has no attribute 'errors'

During handling of the above exception, another exception occurred:

Traceback (most recent call last):
  File "/Users/ughestaff/.local/share/virtualenvs/Codes-vPfYgZ7o/lib/python3.10/site-packages/django/template/base.py", line 843, in _resolve_lookup
    current = current[int(bit)]
ValueError: invalid literal for int() with base 10: 'errors'

During handling of the above exception, another exception occurred:

Traceback (most recent call last):
  File "/Users/ughestaff/.local/share/virtualenvs/Codes-vPfYgZ7o/lib/python3.10/site-packages/django/template/base.py", line 848, in _resolve_lookup
    raise VariableDoesNotExist("Failed lookup for key "
django.template.base.VariableDoesNotExist: Failed lookup for key [errors] in None
Exception while resolving variable 'show' in template 'admin/change_list.html'.
Traceback (most recent call last):
  File "/Users/ughestaff/.local/share/virtualenvs/Codes-vPfYgZ7o/lib/python3.10/site-packages/django/template/base.py", line 829, in _resolve_lookup
    current = current[bit]
  File "/Users/ughestaff/.local/share/virtualenvs/Codes-vPfYgZ7o/lib/python3.10/site-packages/django/template/context.py", line 83, in __getitem__
    raise KeyError(key)
KeyError: 'show'

During handling of the above exception, another exception occurred:

Traceback (most recent call last):
  File "/Users/ughestaff/.local/share/virtualenvs/Codes-vPfYgZ7o/lib/python3.10/site-packages/django/template/base.py", line 835, in _resolve_lookup
    if isinstance(current, BaseContext) and getattr(type(current), bit):
AttributeError: type object 'RequestContext' has no attribute 'show'

During handling of the above exception, another exception occurred:

Traceback (most recent call last):
  File "/Users/ughestaff/.local/share/virtualenvs/Codes-vPfYgZ7o/lib/python3.10/site-packages/django/template/base.py", line 843, in _resolve_lookup
    current = current[int(bit)]
ValueError: invalid literal for int() with base 10: 'show'

During handling of the above exception, another exception occurred:

Traceback (most recent call last):
  File "/Users/ughestaff/.local/share/virtualenvs/Codes-vPfYgZ7o/lib/python3.10/site-packages/django/template/base.py", line 848, in _resolve_lookup
    raise VariableDoesNotExist("Failed lookup for key "
django.template.base.VariableDoesNotExist: Failed lookup for key [show] in [{'True': True, 'False': False, 'None': None, 'csrf_token': <SimpleLazyObject: <function csrf.<locals>._get_val at 0x104dabac0>>}]
Exception while resolving variable 'is_multipart' in template 'admin/change_list.html'.
Traceback (most recent call last):
  File "/Users/ughestaff/.local/share/virtualenvs/Codes-vPfYgZ7o/lib/python3.10/site-packages/django/template/base.py", line 829, in _resolve_lookup
    current = current[bit]
TypeError: 'NoneType' object is not subscriptable

During handling of the above exception, another exception occurred:

Traceback (most recent call last):
  File "/Users/ughestaff/.local/share/virtualenvs/Codes-vPfYgZ7o/lib/python3.10/site-packages/django/template/base.py", line 837, in _resolve_lookup
    current = getattr(current, bit)
AttributeError: 'NoneType' object has no attribute 'is_multipart'

During handling of the above exception, another exception occurred:

Traceback (most recent call last):
  File "/Users/ughestaff/.local/share/virtualenvs/Codes-vPfYgZ7o/lib/python3.10/site-packages/django/template/base.py", line 843, in _resolve_lookup
    current = current[int(bit)]
ValueError: invalid literal for int() with base 10: 'is_multipart'

During handling of the above exception, another exception occurred:

Traceback (most recent call last):
  File "/Users/ughestaff/.local/share/virtualenvs/Codes-vPfYgZ7o/lib/python3.10/site-packages/django/template/base.py", line 848, in _resolve_lookup
    raise VariableDoesNotExist("Failed lookup for key "
django.template.base.VariableDoesNotExist: Failed lookup for key [is_multipart] in None
Exception while resolving variable 'non_field_errors' in template 'admin/change_list.html'.
Traceback (most recent call last):
  File "/Users/ughestaff/.local/share/virtualenvs/Codes-vPfYgZ7o/lib/python3.10/site-packages/django/template/base.py", line 829, in _resolve_lookup
    current = current[bit]
TypeError: 'NoneType' object is not subscriptable

During handling of the above exception, another exception occurred:

Traceback (most recent call last):
  File "/Users/ughestaff/.local/share/virtualenvs/Codes-vPfYgZ7o/lib/python3.10/site-packages/django/template/base.py", line 837, in _resolve_lookup
    current = getattr(current, bit)
AttributeError: 'NoneType' object has no attribute 'non_field_errors'

During handling of the above exception, another exception occurred:

Traceback (most recent call last):
  File "/Users/ughestaff/.local/share/virtualenvs/Codes-vPfYgZ7o/lib/python3.10/site-packages/django/template/base.py", line 843, in _resolve_lookup
    current = current[int(bit)]
ValueError: invalid literal for int() with base 10: 'non_field_errors'

During handling of the above exception, another exception occurred:

Traceback (most recent call last):
  File "/Users/ughestaff/.local/share/virtualenvs/Codes-vPfYgZ7o/lib/python3.10/site-packages/django/template/base.py", line 848, in _resolve_lookup
    raise VariableDoesNotExist("Failed lookup for key "
django.template.base.VariableDoesNotExist: Failed lookup for key [non_field_errors] in None
Exception while resolving variable 'non_field_errors' in template 'admin/change_list.html'.
Traceback (most recent call last):
  File "/Users/ughestaff/.local/share/virtualenvs/Codes-vPfYgZ7o/lib/python3.10/site-packages/django/template/base.py", line 829, in _resolve_lookup
    current = current[bit]
TypeError: 'NoneType' object is not subscriptable

During handling of the above exception, another exception occurred:

Traceback (most recent call last):
  File "/Users/ughestaff/.local/share/virtualenvs/Codes-vPfYgZ7o/lib/python3.10/site-packages/django/template/base.py", line 837, in _resolve_lookup
    current = getattr(current, bit)
AttributeError: 'NoneType' object has no attribute 'non_field_errors'

During handling of the above exception, another exception occurred:

Traceback (most recent call last):
  File "/Users/ughestaff/.local/share/virtualenvs/Codes-vPfYgZ7o/lib/python3.10/site-packages/django/template/base.py", line 843, in _resolve_lookup
    current = current[int(bit)]
ValueError: invalid literal for int() with base 10: 'non_field_errors'

During handling of the above exception, another exception occurred:

Traceback (most recent call last):
  File "/Users/ughestaff/.local/share/virtualenvs/Codes-vPfYgZ7o/lib/python3.10/site-packages/django/template/base.py", line 848, in _resolve_lookup
    raise VariableDoesNotExist("Failed lookup for key "
django.template.base.VariableDoesNotExist: Failed lookup for key [non_field_errors] in None
Exception while resolving variable 'non_field_errors' in template 'admin/change_list.html'.
Traceback (most recent call last):
  File "/Users/ughestaff/.local/share/virtualenvs/Codes-vPfYgZ7o/lib/python3.10/site-packages/django/template/base.py", line 829, in _resolve_lookup
    current = current[bit]
TypeError: 'NoneType' object is not subscriptable

During handling of the above exception, another exception occurred:

Traceback (most recent call last):
  File "/Users/ughestaff/.local/share/virtualenvs/Codes-vPfYgZ7o/lib/python3.10/site-packages/django/template/base.py", line 837, in _resolve_lookup
    current = getattr(current, bit)
AttributeError: 'NoneType' object has no attribute 'non_field_errors'

During handling of the above exception, another exception occurred:

Traceback (most recent call last):
  File "/Users/ughestaff/.local/share/virtualenvs/Codes-vPfYgZ7o/lib/python3.10/site-packages/django/template/base.py", line 843, in _resolve_lookup
    current = current[int(bit)]
ValueError: invalid literal for int() with base 10: 'non_field_errors'

During handling of the above exception, another exception occurred:

Traceback (most recent call last):
  File "/Users/ughestaff/.local/share/virtualenvs/Codes-vPfYgZ7o/lib/python3.10/site-packages/django/template/base.py", line 848, in _resolve_lookup
    raise VariableDoesNotExist("Failed lookup for key "
django.template.base.VariableDoesNotExist: Failed lookup for key [non_field_errors] in None
Exception while resolving variable 'non_field_errors' in template 'admin/change_list.html'.
Traceback (most recent call last):
  File "/Users/ughestaff/.local/share/virtualenvs/Codes-vPfYgZ7o/lib/python3.10/site-packages/django/template/base.py", line 829, in _resolve_lookup
    current = current[bit]
TypeError: 'NoneType' object is not subscriptable

During handling of the above exception, another exception occurred:

Traceback (most recent call last):
  File "/Users/ughestaff/.local/share/virtualenvs/Codes-vPfYgZ7o/lib/python3.10/site-packages/django/template/base.py", line 837, in _resolve_lookup
    current = getattr(current, bit)
AttributeError: 'NoneType' object has no attribute 'non_field_errors'

During handling of the above exception, another exception occurred:

Traceback (most recent call last):
  File "/Users/ughestaff/.local/share/virtualenvs/Codes-vPfYgZ7o/lib/python3.10/site-packages/django/template/base.py", line 843, in _resolve_lookup
    current = current[int(bit)]
ValueError: invalid literal for int() with base 10: 'non_field_errors'

During handling of the above exception, another exception occurred:

Traceback (most recent call last):
  File "/Users/ughestaff/.local/share/virtualenvs/Codes-vPfYgZ7o/lib/python3.10/site-packages/django/template/base.py", line 848, in _resolve_lookup
    raise VariableDoesNotExist("Failed lookup for key "
django.template.base.VariableDoesNotExist: Failed lookup for key [non_field_errors] in None
Exception while resolving variable 'non_field_errors' in template 'admin/change_list.html'.
Traceback (most recent call last):
  File "/Users/ughestaff/.local/share/virtualenvs/Codes-vPfYgZ7o/lib/python3.10/site-packages/django/template/base.py", line 829, in _resolve_lookup
    current = current[bit]
TypeError: 'NoneType' object is not subscriptable

During handling of the above exception, another exception occurred:

Traceback (most recent call last):
  File "/Users/ughestaff/.local/share/virtualenvs/Codes-vPfYgZ7o/lib/python3.10/site-packages/django/template/base.py", line 837, in _resolve_lookup
    current = getattr(current, bit)
AttributeError: 'NoneType' object has no attribute 'non_field_errors'

During handling of the above exception, another exception occurred:

Traceback (most recent call last):
  File "/Users/ughestaff/.local/share/virtualenvs/Codes-vPfYgZ7o/lib/python3.10/site-packages/django/template/base.py", line 843, in _resolve_lookup
    current = current[int(bit)]
ValueError: invalid literal for int() with base 10: 'non_field_errors'

During handling of the above exception, another exception occurred:

Traceback (most recent call last):
  File "/Users/ughestaff/.local/share/virtualenvs/Codes-vPfYgZ7o/lib/python3.10/site-packages/django/template/base.py", line 848, in _resolve_lookup
    raise VariableDoesNotExist("Failed lookup for key "
django.template.base.VariableDoesNotExist: Failed lookup for key [non_field_errors] in None
Exception while resolving variable 'non_field_errors' in template 'admin/change_list.html'.
Traceback (most recent call last):
  File "/Users/ughestaff/.local/share/virtualenvs/Codes-vPfYgZ7o/lib/python3.10/site-packages/django/template/base.py", line 829, in _resolve_lookup
    current = current[bit]
TypeError: 'NoneType' object is not subscriptable

During handling of the above exception, another exception occurred:

Traceback (most recent call last):
  File "/Users/ughestaff/.local/share/virtualenvs/Codes-vPfYgZ7o/lib/python3.10/site-packages/django/template/base.py", line 837, in _resolve_lookup
    current = getattr(current, bit)
AttributeError: 'NoneType' object has no attribute 'non_field_errors'

During handling of the above exception, another exception occurred:

Traceback (most recent call last):
  File "/Users/ughestaff/.local/share/virtualenvs/Codes-vPfYgZ7o/lib/python3.10/site-packages/django/template/base.py", line 843, in _resolve_lookup
    current = current[int(bit)]
ValueError: invalid literal for int() with base 10: 'non_field_errors'

During handling of the above exception, another exception occurred:

Traceback (most recent call last):
  File "/Users/ughestaff/.local/share/virtualenvs/Codes-vPfYgZ7o/lib/python3.10/site-packages/django/template/base.py", line 848, in _resolve_lookup
    raise VariableDoesNotExist("Failed lookup for key "
django.template.base.VariableDoesNotExist: Failed lookup for key [non_field_errors] in None
Exception while resolving variable 'non_field_errors' in template 'admin/change_list.html'.
Traceback (most recent call last):
  File "/Users/ughestaff/.local/share/virtualenvs/Codes-vPfYgZ7o/lib/python3.10/site-packages/django/template/base.py", line 829, in _resolve_lookup
    current = current[bit]
TypeError: 'NoneType' object is not subscriptable

During handling of the above exception, another exception occurred:

Traceback (most recent call last):
  File "/Users/ughestaff/.local/share/virtualenvs/Codes-vPfYgZ7o/lib/python3.10/site-packages/django/template/base.py", line 837, in _resolve_lookup
    current = getattr(current, bit)
AttributeError: 'NoneType' object has no attribute 'non_field_errors'

During handling of the above exception, another exception occurred:

Traceback (most recent call last):
  File "/Users/ughestaff/.local/share/virtualenvs/Codes-vPfYgZ7o/lib/python3.10/site-packages/django/template/base.py", line 843, in _resolve_lookup
    current = current[int(bit)]
ValueError: invalid literal for int() with base 10: 'non_field_errors'

During handling of the above exception, another exception occurred:

Traceback (most recent call last):
  File "/Users/ughestaff/.local/share/virtualenvs/Codes-vPfYgZ7o/lib/python3.10/site-packages/django/template/base.py", line 848, in _resolve_lookup
    raise VariableDoesNotExist("Failed lookup for key "
django.template.base.VariableDoesNotExist: Failed lookup for key [non_field_errors] in None
Exception while resolving variable 'non_field_errors' in template 'admin/change_list.html'.
Traceback (most recent call last):
  File "/Users/ughestaff/.local/share/virtualenvs/Codes-vPfYgZ7o/lib/python3.10/site-packages/django/template/base.py", line 829, in _resolve_lookup
    current = current[bit]
TypeError: 'NoneType' object is not subscriptable

During handling of the above exception, another exception occurred:

Traceback (most recent call last):
  File "/Users/ughestaff/.local/share/virtualenvs/Codes-vPfYgZ7o/lib/python3.10/site-packages/django/template/base.py", line 837, in _resolve_lookup
    current = getattr(current, bit)
AttributeError: 'NoneType' object has no attribute 'non_field_errors'

During handling of the above exception, another exception occurred:

Traceback (most recent call last):
  File "/Users/ughestaff/.local/share/virtualenvs/Codes-vPfYgZ7o/lib/python3.10/site-packages/django/template/base.py", line 843, in _resolve_lookup
    current = current[int(bit)]
ValueError: invalid literal for int() with base 10: 'non_field_errors'

During handling of the above exception, another exception occurred:

Traceback (most recent call last):
  File "/Users/ughestaff/.local/share/virtualenvs/Codes-vPfYgZ7o/lib/python3.10/site-packages/django/template/base.py", line 848, in _resolve_lookup
    raise VariableDoesNotExist("Failed lookup for key "
django.template.base.VariableDoesNotExist: Failed lookup for key [non_field_errors] in None
Exception while resolving variable 'non_field_errors' in template 'admin/change_list.html'.
Traceback (most recent call last):
  File "/Users/ughestaff/.local/share/virtualenvs/Codes-vPfYgZ7o/lib/python3.10/site-packages/django/template/base.py", line 829, in _resolve_lookup
    current = current[bit]
TypeError: 'NoneType' object is not subscriptable

During handling of the above exception, another exception occurred:

Traceback (most recent call last):
  File "/Users/ughestaff/.local/share/virtualenvs/Codes-vPfYgZ7o/lib/python3.10/site-packages/django/template/base.py", line 837, in _resolve_lookup
    current = getattr(current, bit)
AttributeError: 'NoneType' object has no attribute 'non_field_errors'

During handling of the above exception, another exception occurred:

Traceback (most recent call last):
  File "/Users/ughestaff/.local/share/virtualenvs/Codes-vPfYgZ7o/lib/python3.10/site-packages/django/template/base.py", line 843, in _resolve_lookup
    current = current[int(bit)]
ValueError: invalid literal for int() with base 10: 'non_field_errors'

During handling of the above exception, another exception occurred:

Traceback (most recent call last):
  File "/Users/ughestaff/.local/share/virtualenvs/Codes-vPfYgZ7o/lib/python3.10/site-packages/django/template/base.py", line 848, in _resolve_lookup
    raise VariableDoesNotExist("Failed lookup for key "
django.template.base.VariableDoesNotExist: Failed lookup for key [non_field_errors] in None
Exception while resolving variable 'non_field_errors' in template 'admin/change_list.html'.
Traceback (most recent call last):
  File "/Users/ughestaff/.local/share/virtualenvs/Codes-vPfYgZ7o/lib/python3.10/site-packages/django/template/base.py", line 829, in _resolve_lookup
    current = current[bit]
TypeError: 'NoneType' object is not subscriptable

During handling of the above exception, another exception occurred:

Traceback (most recent call last):
  File "/Users/ughestaff/.local/share/virtualenvs/Codes-vPfYgZ7o/lib/python3.10/site-packages/django/template/base.py", line 837, in _resolve_lookup
    current = getattr(current, bit)
AttributeError: 'NoneType' object has no attribute 'non_field_errors'

During handling of the above exception, another exception occurred:

Traceback (most recent call last):
  File "/Users/ughestaff/.local/share/virtualenvs/Codes-vPfYgZ7o/lib/python3.10/site-packages/django/template/base.py", line 843, in _resolve_lookup
    current = current[int(bit)]
ValueError: invalid literal for int() with base 10: 'non_field_errors'

During handling of the above exception, another exception occurred:

Traceback (most recent call last):
  File "/Users/ughestaff/.local/share/virtualenvs/Codes-vPfYgZ7o/lib/python3.10/site-packages/django/template/base.py", line 848, in _resolve_lookup
    raise VariableDoesNotExist("Failed lookup for key "
django.template.base.VariableDoesNotExist: Failed lookup for key [non_field_errors] in None
"GET /admin/donate/donor/ HTTP/1.1" 200 6295
"GET /static/admin/css/changelists.css HTTP/1.1" 200 6170
"GET /admin/jsi18n/ HTTP/1.1" 200 3185
"GET /static/admin/js/jquery.init.js HTTP/1.1" 200 363
"GET /static/admin/js/vendor/jquery/jquery.min.js HTTP/1.1" 304 0
"GET /static/admin/js/prepopulate.min.js HTTP/1.1" 200 379
"GET /static/admin/js/admin/RelatedObjectLookups.js HTTP/1.1" 304 0
"GET /static/admin/js/core.js HTTP/1.1" 304 0
"GET /static/admin/js/actions.min.js HTTP/1.1" 304 0
"GET /static/admin/js/urlify.js HTTP/1.1" 304 0
"GET /static/admin/js/vendor/xregexp/xregexp.min.js HTTP/1.1" 304 0
"GET /static/admin/img/tooltag-add.svg HTTP/1.1" 200 331
"GET /admin/donate/donor/11/change/ HTTP/1.1" 200 9238
"GET /admin/jsi18n/ HTTP/1.1" 200 3185
"GET /static/admin/css/forms.css HTTP/1.1" 200 8505
"GET /static/admin/js/change_form.js HTTP/1.1" 200 712
"GET /static/admin/js/prepopulate_init.js HTTP/1.1" 200 495
"GET /static/admin/js/calendar.js HTTP/1.1" 304 0
"GET /static/admin/js/admin/DateTimeShortcuts.js HTTP/1.1" 304 0
"GET /static/admin/css/widgets.css HTTP/1.1" 200 10340
"GET /static/admin/img/icon-clock.svg HTTP/1.1" 200 677
"GET /static/admin/img/icon-calendar.svg HTTP/1.1" 200 1086
Exception while resolving variable 'fname' in template 'authentication/user.html'.
Traceback (most recent call last):
  File "/Users/ughestaff/.local/share/virtualenvs/Codes-vPfYgZ7o/lib/python3.10/site-packages/django/template/base.py", line 829, in _resolve_lookup
    current = current[bit]
  File "/Users/ughestaff/.local/share/virtualenvs/Codes-vPfYgZ7o/lib/python3.10/site-packages/django/template/context.py", line 83, in __getitem__
    raise KeyError(key)
KeyError: 'fname'

During handling of the above exception, another exception occurred:

Traceback (most recent call last):
  File "/Users/ughestaff/.local/share/virtualenvs/Codes-vPfYgZ7o/lib/python3.10/site-packages/django/template/base.py", line 835, in _resolve_lookup
    if isinstance(current, BaseContext) and getattr(type(current), bit):
AttributeError: type object 'RequestContext' has no attribute 'fname'

During handling of the above exception, another exception occurred:

Traceback (most recent call last):
  File "/Users/ughestaff/.local/share/virtualenvs/Codes-vPfYgZ7o/lib/python3.10/site-packages/django/template/base.py", line 843, in _resolve_lookup
    current = current[int(bit)]
ValueError: invalid literal for int() with base 10: 'fname'

During handling of the above exception, another exception occurred:

Traceback (most recent call last):
  File "/Users/ughestaff/.local/share/virtualenvs/Codes-vPfYgZ7o/lib/python3.10/site-packages/django/template/base.py", line 848, in _resolve_lookup
    raise VariableDoesNotExist("Failed lookup for key "
django.template.base.VariableDoesNotExist: Failed lookup for key [fname] in [{'True': True, 'False': False, 'None': None}, {'csrf_token': <SimpleLazyObject: <function csrf.<locals>._get_val at 0x104f030a0>>, 'request': <WSGIRequest: POST '/donate'>, 'user': <SimpleLazyObject: <User: Lil>>, 'perms': <django.contrib.auth.context_processors.PermWrapper object at 0x104f74ca0>, 'messages': <django.contrib.messages.storage.fallback.FallbackStorage object at 0x104f5a380>, 'DEFAULT_MESSAGE_LEVELS': {'DEBUG': 10, 'INFO': 20, 'SUCCESS': 25, 'WARNING': 30, 'ERROR': 40}}, {}]
"POST /donate HTTP/1.1" 200 5342
"GET /static/css/main.css HTTP/1.1" 304 0
"GET /static/Images/email-box.jpeg HTTP/1.1" 304 0
"GET /static/Images/Logo.jpeg HTTP/1.1" 304 0
Not Found: /static/node_modules/bulma/bulma
"GET /static/node_modules/bulma/bulma HTTP/1.1" 404 105
"GET /static/Images/Background2.jpeg HTTP/1.1" 304 0
Exception while resolving variable 'errors' in template 'admin/change_list.html'.
Traceback (most recent call last):
  File "/Users/ughestaff/.local/share/virtualenvs/Codes-vPfYgZ7o/lib/python3.10/site-packages/django/template/base.py", line 829, in _resolve_lookup
    current = current[bit]
TypeError: 'NoneType' object is not subscriptable

During handling of the above exception, another exception occurred:

Traceback (most recent call last):
  File "/Users/ughestaff/.local/share/virtualenvs/Codes-vPfYgZ7o/lib/python3.10/site-packages/django/template/base.py", line 837, in _resolve_lookup
    current = getattr(current, bit)
AttributeError: 'NoneType' object has no attribute 'errors'

During handling of the above exception, another exception occurred:

Traceback (most recent call last):
  File "/Users/ughestaff/.local/share/virtualenvs/Codes-vPfYgZ7o/lib/python3.10/site-packages/django/template/base.py", line 843, in _resolve_lookup
    current = current[int(bit)]
ValueError: invalid literal for int() with base 10: 'errors'

During handling of the above exception, another exception occurred:

Traceback (most recent call last):
  File "/Users/ughestaff/.local/share/virtualenvs/Codes-vPfYgZ7o/lib/python3.10/site-packages/django/template/base.py", line 848, in _resolve_lookup
    raise VariableDoesNotExist("Failed lookup for key "
django.template.base.VariableDoesNotExist: Failed lookup for key [errors] in None
Exception while resolving variable 'show' in template 'admin/change_list.html'.
Traceback (most recent call last):
  File "/Users/ughestaff/.local/share/virtualenvs/Codes-vPfYgZ7o/lib/python3.10/site-packages/django/template/base.py", line 829, in _resolve_lookup
    current = current[bit]
  File "/Users/ughestaff/.local/share/virtualenvs/Codes-vPfYgZ7o/lib/python3.10/site-packages/django/template/context.py", line 83, in __getitem__
    raise KeyError(key)
KeyError: 'show'

During handling of the above exception, another exception occurred:

Traceback (most recent call last):
  File "/Users/ughestaff/.local/share/virtualenvs/Codes-vPfYgZ7o/lib/python3.10/site-packages/django/template/base.py", line 835, in _resolve_lookup
    if isinstance(current, BaseContext) and getattr(type(current), bit):
AttributeError: type object 'RequestContext' has no attribute 'show'

During handling of the above exception, another exception occurred:

Traceback (most recent call last):
  File "/Users/ughestaff/.local/share/virtualenvs/Codes-vPfYgZ7o/lib/python3.10/site-packages/django/template/base.py", line 843, in _resolve_lookup
    current = current[int(bit)]
ValueError: invalid literal for int() with base 10: 'show'

During handling of the above exception, another exception occurred:

Traceback (most recent call last):
  File "/Users/ughestaff/.local/share/virtualenvs/Codes-vPfYgZ7o/lib/python3.10/site-packages/django/template/base.py", line 848, in _resolve_lookup
    raise VariableDoesNotExist("Failed lookup for key "
django.template.base.VariableDoesNotExist: Failed lookup for key [show] in [{'True': True, 'False': False, 'None': None, 'csrf_token': <SimpleLazyObject: <function csrf.<locals>._get_val at 0x104dabac0>>}]
Exception while resolving variable 'is_multipart' in template 'admin/change_list.html'.
Traceback (most recent call last):
  File "/Users/ughestaff/.local/share/virtualenvs/Codes-vPfYgZ7o/lib/python3.10/site-packages/django/template/base.py", line 829, in _resolve_lookup
    current = current[bit]
TypeError: 'NoneType' object is not subscriptable

During handling of the above exception, another exception occurred:

Traceback (most recent call last):
  File "/Users/ughestaff/.local/share/virtualenvs/Codes-vPfYgZ7o/lib/python3.10/site-packages/django/template/base.py", line 837, in _resolve_lookup
    current = getattr(current, bit)
AttributeError: 'NoneType' object has no attribute 'is_multipart'

During handling of the above exception, another exception occurred:

Traceback (most recent call last):
  File "/Users/ughestaff/.local/share/virtualenvs/Codes-vPfYgZ7o/lib/python3.10/site-packages/django/template/base.py", line 843, in _resolve_lookup
    current = current[int(bit)]
ValueError: invalid literal for int() with base 10: 'is_multipart'

During handling of the above exception, another exception occurred:

Traceback (most recent call last):
  File "/Users/ughestaff/.local/share/virtualenvs/Codes-vPfYgZ7o/lib/python3.10/site-packages/django/template/base.py", line 848, in _resolve_lookup
    raise VariableDoesNotExist("Failed lookup for key "
django.template.base.VariableDoesNotExist: Failed lookup for key [is_multipart] in None
Exception while resolving variable 'non_field_errors' in template 'admin/change_list.html'.
Traceback (most recent call last):
  File "/Users/ughestaff/.local/share/virtualenvs/Codes-vPfYgZ7o/lib/python3.10/site-packages/django/template/base.py", line 829, in _resolve_lookup
    current = current[bit]
TypeError: 'NoneType' object is not subscriptable

During handling of the above exception, another exception occurred:

Traceback (most recent call last):
  File "/Users/ughestaff/.local/share/virtualenvs/Codes-vPfYgZ7o/lib/python3.10/site-packages/django/template/base.py", line 837, in _resolve_lookup
    current = getattr(current, bit)
AttributeError: 'NoneType' object has no attribute 'non_field_errors'

During handling of the above exception, another exception occurred:

Traceback (most recent call last):
  File "/Users/ughestaff/.local/share/virtualenvs/Codes-vPfYgZ7o/lib/python3.10/site-packages/django/template/base.py", line 843, in _resolve_lookup
    current = current[int(bit)]
ValueError: invalid literal for int() with base 10: 'non_field_errors'

During handling of the above exception, another exception occurred:

Traceback (most recent call last):
  File "/Users/ughestaff/.local/share/virtualenvs/Codes-vPfYgZ7o/lib/python3.10/site-packages/django/template/base.py", line 848, in _resolve_lookup
    raise VariableDoesNotExist("Failed lookup for key "
django.template.base.VariableDoesNotExist: Failed lookup for key [non_field_errors] in None
Exception while resolving variable 'non_field_errors' in template 'admin/change_list.html'.
Traceback (most recent call last):
  File "/Users/ughestaff/.local/share/virtualenvs/Codes-vPfYgZ7o/lib/python3.10/site-packages/django/template/base.py", line 829, in _resolve_lookup
    current = current[bit]
TypeError: 'NoneType' object is not subscriptable

During handling of the above exception, another exception occurred:

Traceback (most recent call last):
  File "/Users/ughestaff/.local/share/virtualenvs/Codes-vPfYgZ7o/lib/python3.10/site-packages/django/template/base.py", line 837, in _resolve_lookup
    current = getattr(current, bit)
AttributeError: 'NoneType' object has no attribute 'non_field_errors'

During handling of the above exception, another exception occurred:

Traceback (most recent call last):
  File "/Users/ughestaff/.local/share/virtualenvs/Codes-vPfYgZ7o/lib/python3.10/site-packages/django/template/base.py", line 843, in _resolve_lookup
    current = current[int(bit)]
ValueError: invalid literal for int() with base 10: 'non_field_errors'

During handling of the above exception, another exception occurred:

Traceback (most recent call last):
  File "/Users/ughestaff/.local/share/virtualenvs/Codes-vPfYgZ7o/lib/python3.10/site-packages/django/template/base.py", line 848, in _resolve_lookup
    raise VariableDoesNotExist("Failed lookup for key "
django.template.base.VariableDoesNotExist: Failed lookup for key [non_field_errors] in None
Exception while resolving variable 'non_field_errors' in template 'admin/change_list.html'.
Traceback (most recent call last):
  File "/Users/ughestaff/.local/share/virtualenvs/Codes-vPfYgZ7o/lib/python3.10/site-packages/django/template/base.py", line 829, in _resolve_lookup
    current = current[bit]
TypeError: 'NoneType' object is not subscriptable

During handling of the above exception, another exception occurred:

Traceback (most recent call last):
  File "/Users/ughestaff/.local/share/virtualenvs/Codes-vPfYgZ7o/lib/python3.10/site-packages/django/template/base.py", line 837, in _resolve_lookup
    current = getattr(current, bit)
AttributeError: 'NoneType' object has no attribute 'non_field_errors'

During handling of the above exception, another exception occurred:

Traceback (most recent call last):
  File "/Users/ughestaff/.local/share/virtualenvs/Codes-vPfYgZ7o/lib/python3.10/site-packages/django/template/base.py", line 843, in _resolve_lookup
    current = current[int(bit)]
ValueError: invalid literal for int() with base 10: 'non_field_errors'

During handling of the above exception, another exception occurred:

Traceback (most recent call last):
  File "/Users/ughestaff/.local/share/virtualenvs/Codes-vPfYgZ7o/lib/python3.10/site-packages/django/template/base.py", line 848, in _resolve_lookup
    raise VariableDoesNotExist("Failed lookup for key "
django.template.base.VariableDoesNotExist: Failed lookup for key [non_field_errors] in None
Exception while resolving variable 'non_field_errors' in template 'admin/change_list.html'.
Traceback (most recent call last):
  File "/Users/ughestaff/.local/share/virtualenvs/Codes-vPfYgZ7o/lib/python3.10/site-packages/django/template/base.py", line 829, in _resolve_lookup
    current = current[bit]
TypeError: 'NoneType' object is not subscriptable

During handling of the above exception, another exception occurred:

Traceback (most recent call last):
  File "/Users/ughestaff/.local/share/virtualenvs/Codes-vPfYgZ7o/lib/python3.10/site-packages/django/template/base.py", line 837, in _resolve_lookup
    current = getattr(current, bit)
AttributeError: 'NoneType' object has no attribute 'non_field_errors'

During handling of the above exception, another exception occurred:

Traceback (most recent call last):
  File "/Users/ughestaff/.local/share/virtualenvs/Codes-vPfYgZ7o/lib/python3.10/site-packages/django/template/base.py", line 843, in _resolve_lookup
    current = current[int(bit)]
ValueError: invalid literal for int() with base 10: 'non_field_errors'

During handling of the above exception, another exception occurred:

Traceback (most recent call last):
  File "/Users/ughestaff/.local/share/virtualenvs/Codes-vPfYgZ7o/lib/python3.10/site-packages/django/template/base.py", line 848, in _resolve_lookup
    raise VariableDoesNotExist("Failed lookup for key "
django.template.base.VariableDoesNotExist: Failed lookup for key [non_field_errors] in None
Exception while resolving variable 'non_field_errors' in template 'admin/change_list.html'.
Traceback (most recent call last):
  File "/Users/ughestaff/.local/share/virtualenvs/Codes-vPfYgZ7o/lib/python3.10/site-packages/django/template/base.py", line 829, in _resolve_lookup
    current = current[bit]
TypeError: 'NoneType' object is not subscriptable

During handling of the above exception, another exception occurred:

Traceback (most recent call last):
  File "/Users/ughestaff/.local/share/virtualenvs/Codes-vPfYgZ7o/lib/python3.10/site-packages/django/template/base.py", line 837, in _resolve_lookup
    current = getattr(current, bit)
AttributeError: 'NoneType' object has no attribute 'non_field_errors'

During handling of the above exception, another exception occurred:

Traceback (most recent call last):
  File "/Users/ughestaff/.local/share/virtualenvs/Codes-vPfYgZ7o/lib/python3.10/site-packages/django/template/base.py", line 843, in _resolve_lookup
    current = current[int(bit)]
ValueError: invalid literal for int() with base 10: 'non_field_errors'

During handling of the above exception, another exception occurred:

Traceback (most recent call last):
  File "/Users/ughestaff/.local/share/virtualenvs/Codes-vPfYgZ7o/lib/python3.10/site-packages/django/template/base.py", line 848, in _resolve_lookup
    raise VariableDoesNotExist("Failed lookup for key "
django.template.base.VariableDoesNotExist: Failed lookup for key [non_field_errors] in None
Exception while resolving variable 'non_field_errors' in template 'admin/change_list.html'.
Traceback (most recent call last):
  File "/Users/ughestaff/.local/share/virtualenvs/Codes-vPfYgZ7o/lib/python3.10/site-packages/django/template/base.py", line 829, in _resolve_lookup
    current = current[bit]
TypeError: 'NoneType' object is not subscriptable

During handling of the above exception, another exception occurred:

Traceback (most recent call last):
  File "/Users/ughestaff/.local/share/virtualenvs/Codes-vPfYgZ7o/lib/python3.10/site-packages/django/template/base.py", line 837, in _resolve_lookup
    current = getattr(current, bit)
AttributeError: 'NoneType' object has no attribute 'non_field_errors'

During handling of the above exception, another exception occurred:

Traceback (most recent call last):
  File "/Users/ughestaff/.local/share/virtualenvs/Codes-vPfYgZ7o/lib/python3.10/site-packages/django/template/base.py", line 843, in _resolve_lookup
    current = current[int(bit)]
ValueError: invalid literal for int() with base 10: 'non_field_errors'

During handling of the above exception, another exception occurred:

Traceback (most recent call last):
  File "/Users/ughestaff/.local/share/virtualenvs/Codes-vPfYgZ7o/lib/python3.10/site-packages/django/template/base.py", line 848, in _resolve_lookup
    raise VariableDoesNotExist("Failed lookup for key "
django.template.base.VariableDoesNotExist: Failed lookup for key [non_field_errors] in None
Exception while resolving variable 'non_field_errors' in template 'admin/change_list.html'.
Traceback (most recent call last):
  File "/Users/ughestaff/.local/share/virtualenvs/Codes-vPfYgZ7o/lib/python3.10/site-packages/django/template/base.py", line 829, in _resolve_lookup
    current = current[bit]
TypeError: 'NoneType' object is not subscriptable

During handling of the above exception, another exception occurred:

Traceback (most recent call last):
  File "/Users/ughestaff/.local/share/virtualenvs/Codes-vPfYgZ7o/lib/python3.10/site-packages/django/template/base.py", line 837, in _resolve_lookup
    current = getattr(current, bit)
AttributeError: 'NoneType' object has no attribute 'non_field_errors'

During handling of the above exception, another exception occurred:

Traceback (most recent call last):
  File "/Users/ughestaff/.local/share/virtualenvs/Codes-vPfYgZ7o/lib/python3.10/site-packages/django/template/base.py", line 843, in _resolve_lookup
    current = current[int(bit)]
ValueError: invalid literal for int() with base 10: 'non_field_errors'

During handling of the above exception, another exception occurred:

Traceback (most recent call last):
  File "/Users/ughestaff/.local/share/virtualenvs/Codes-vPfYgZ7o/lib/python3.10/site-packages/django/template/base.py", line 848, in _resolve_lookup
    raise VariableDoesNotExist("Failed lookup for key "
django.template.base.VariableDoesNotExist: Failed lookup for key [non_field_errors] in None
Exception while resolving variable 'non_field_errors' in template 'admin/change_list.html'.
Traceback (most recent call last):
  File "/Users/ughestaff/.local/share/virtualenvs/Codes-vPfYgZ7o/lib/python3.10/site-packages/django/template/base.py", line 829, in _resolve_lookup
    current = current[bit]
TypeError: 'NoneType' object is not subscriptable

During handling of the above exception, another exception occurred:

Traceback (most recent call last):
  File "/Users/ughestaff/.local/share/virtualenvs/Codes-vPfYgZ7o/lib/python3.10/site-packages/django/template/base.py", line 837, in _resolve_lookup
    current = getattr(current, bit)
AttributeError: 'NoneType' object has no attribute 'non_field_errors'

During handling of the above exception, another exception occurred:

Traceback (most recent call last):
  File "/Users/ughestaff/.local/share/virtualenvs/Codes-vPfYgZ7o/lib/python3.10/site-packages/django/template/base.py", line 843, in _resolve_lookup
    current = current[int(bit)]
ValueError: invalid literal for int() with base 10: 'non_field_errors'

During handling of the above exception, another exception occurred:

Traceback (most recent call last):
  File "/Users/ughestaff/.local/share/virtualenvs/Codes-vPfYgZ7o/lib/python3.10/site-packages/django/template/base.py", line 848, in _resolve_lookup
    raise VariableDoesNotExist("Failed lookup for key "
django.template.base.VariableDoesNotExist: Failed lookup for key [non_field_errors] in None
Exception while resolving variable 'non_field_errors' in template 'admin/change_list.html'.
Traceback (most recent call last):
  File "/Users/ughestaff/.local/share/virtualenvs/Codes-vPfYgZ7o/lib/python3.10/site-packages/django/template/base.py", line 829, in _resolve_lookup
    current = current[bit]
TypeError: 'NoneType' object is not subscriptable

During handling of the above exception, another exception occurred:

Traceback (most recent call last):
  File "/Users/ughestaff/.local/share/virtualenvs/Codes-vPfYgZ7o/lib/python3.10/site-packages/django/template/base.py", line 837, in _resolve_lookup
    current = getattr(current, bit)
AttributeError: 'NoneType' object has no attribute 'non_field_errors'

During handling of the above exception, another exception occurred:

Traceback (most recent call last):
  File "/Users/ughestaff/.local/share/virtualenvs/Codes-vPfYgZ7o/lib/python3.10/site-packages/django/template/base.py", line 843, in _resolve_lookup
    current = current[int(bit)]
ValueError: invalid literal for int() with base 10: 'non_field_errors'

During handling of the above exception, another exception occurred:

Traceback (most recent call last):
  File "/Users/ughestaff/.local/share/virtualenvs/Codes-vPfYgZ7o/lib/python3.10/site-packages/django/template/base.py", line 848, in _resolve_lookup
    raise VariableDoesNotExist("Failed lookup for key "
django.template.base.VariableDoesNotExist: Failed lookup for key [non_field_errors] in None
Exception while resolving variable 'non_field_errors' in template 'admin/change_list.html'.
Traceback (most recent call last):
  File "/Users/ughestaff/.local/share/virtualenvs/Codes-vPfYgZ7o/lib/python3.10/site-packages/django/template/base.py", line 829, in _resolve_lookup
    current = current[bit]
TypeError: 'NoneType' object is not subscriptable

During handling of the above exception, another exception occurred:

Traceback (most recent call last):
  File "/Users/ughestaff/.local/share/virtualenvs/Codes-vPfYgZ7o/lib/python3.10/site-packages/django/template/base.py", line 837, in _resolve_lookup
    current = getattr(current, bit)
AttributeError: 'NoneType' object has no attribute 'non_field_errors'

During handling of the above exception, another exception occurred:

Traceback (most recent call last):
  File "/Users/ughestaff/.local/share/virtualenvs/Codes-vPfYgZ7o/lib/python3.10/site-packages/django/template/base.py", line 843, in _resolve_lookup
    current = current[int(bit)]
ValueError: invalid literal for int() with base 10: 'non_field_errors'

During handling of the above exception, another exception occurred:

Traceback (most recent call last):
  File "/Users/ughestaff/.local/share/virtualenvs/Codes-vPfYgZ7o/lib/python3.10/site-packages/django/template/base.py", line 848, in _resolve_lookup
    raise VariableDoesNotExist("Failed lookup for key "
django.template.base.VariableDoesNotExist: Failed lookup for key [non_field_errors] in None
Exception while resolving variable 'non_field_errors' in template 'admin/change_list.html'.
Traceback (most recent call last):
  File "/Users/ughestaff/.local/share/virtualenvs/Codes-vPfYgZ7o/lib/python3.10/site-packages/django/template/base.py", line 829, in _resolve_lookup
    current = current[bit]
TypeError: 'NoneType' object is not subscriptable

During handling of the above exception, another exception occurred:

Traceback (most recent call last):
  File "/Users/ughestaff/.local/share/virtualenvs/Codes-vPfYgZ7o/lib/python3.10/site-packages/django/template/base.py", line 837, in _resolve_lookup
    current = getattr(current, bit)
AttributeError: 'NoneType' object has no attribute 'non_field_errors'

During handling of the above exception, another exception occurred:

Traceback (most recent call last):
  File "/Users/ughestaff/.local/share/virtualenvs/Codes-vPfYgZ7o/lib/python3.10/site-packages/django/template/base.py", line 843, in _resolve_lookup
    current = current[int(bit)]
ValueError: invalid literal for int() with base 10: 'non_field_errors'

During handling of the above exception, another exception occurred:

Traceback (most recent call last):
  File "/Users/ughestaff/.local/share/virtualenvs/Codes-vPfYgZ7o/lib/python3.10/site-packages/django/template/base.py", line 848, in _resolve_lookup
    raise VariableDoesNotExist("Failed lookup for key "
django.template.base.VariableDoesNotExist: Failed lookup for key [non_field_errors] in None
"GET /admin/donate/donor/ HTTP/1.1" 200 6513
"GET /static/admin/css/base.css HTTP/1.1" 304 0
"GET /static/admin/css/changelists.css HTTP/1.1" 304 0
"GET /admin/jsi18n/ HTTP/1.1" 200 3185
"GET /static/admin/js/vendor/jquery/jquery.min.js HTTP/1.1" 304 0
"GET /static/admin/js/jquery.init.js HTTP/1.1" 304 0
"GET /static/admin/js/core.js HTTP/1.1" 304 0
"GET /static/admin/js/actions.min.js HTTP/1.1" 304 0
"GET /static/admin/js/urlify.js HTTP/1.1" 304 0
"GET /static/admin/js/vendor/xregexp/xregexp.min.js HTTP/1.1" 304 0
"GET /static/admin/css/responsive.css HTTP/1.1" 304 0
"GET /static/admin/js/admin/RelatedObjectLookups.js HTTP/1.1" 304 0
"GET /static/admin/js/prepopulate.min.js HTTP/1.1" 304 0
"GET /static/admin/css/fonts.css HTTP/1.1" 304 0
"GET /static/admin/img/tooltag-add.svg HTTP/1.1" 304 0
"GET /admin/donate/donor/12/change/ HTTP/1.1" 200 9270
"GET /static/admin/css/forms.css HTTP/1.1" 304 0
"GET /admin/jsi18n/ HTTP/1.1" 200 3185
"GET /static/admin/js/change_form.js HTTP/1.1" 304 0
"GET /static/admin/js/admin/DateTimeShortcuts.js HTTP/1.1" 304 0
"GET /static/admin/js/calendar.js HTTP/1.1" 304 0
"GET /static/admin/js/prepopulate_init.js HTTP/1.1" 304 0
"GET /static/admin/css/widgets.css HTTP/1.1" 304 0
"GET /static/admin/img/icon-calendar.svg HTTP/1.1" 304 0
"GET /static/admin/img/icon-clock.svg HTTP/1.1" 304 0
