[23/Apr/2022 19:50:51] ERROR [django.request:222] Internal Server Error: /donate
Traceback (most recent call last):
  File "/Users/ughestaff/.local/share/virtualenvs/Codes-vPfYgZ7o/lib/python3.10/site-packages/django/core/handlers/exception.py", line 34, in inner
    response = get_response(request)
  File "/Users/ughestaff/.local/share/virtualenvs/Codes-vPfYgZ7o/lib/python3.10/site-packages/django/core/handlers/base.py", line 126, in _get_response
    response = self.process_exception_by_middleware(e, request)
  File "/Users/ughestaff/.local/share/virtualenvs/Codes-vPfYgZ7o/lib/python3.10/site-packages/django/core/handlers/base.py", line 124, in _get_response
    response = wrapped_callback(request, *callback_args, **callback_kwargs)
  File "/Users/ughestaff/OneDrive - IU International University of Applied Sciences/School/Subjects/In Progress/Project Software Engineering/BloodLoof/2. Development Phase/Codes/donate/views.py", line 28, in donate
    password = request.user.password1
  File "/Users/ughestaff/.local/share/virtualenvs/Codes-vPfYgZ7o/lib/python3.10/site-packages/django/utils/functional.py", line 214, in inner
    return func(self._wrapped, *args)
AttributeError: 'User' object has no attribute 'password1'
[23/Apr/2022 19:50:51] ERROR [django.server:124] "POST /donate HTTP/1.1" 500 27
[23/Apr/2022 19:50:53] ERROR [django.request:222] Internal Server Error: /donate
Traceback (most recent call last):
  File "/Users/ughestaff/.local/share/virtualenvs/Codes-vPfYgZ7o/lib/python3.10/site-packages/django/core/handlers/exception.py", line 34, in inner
    response = get_response(request)
  File "/Users/ughestaff/.local/share/virtualenvs/Codes-vPfYgZ7o/lib/python3.10/site-packages/django/core/handlers/base.py", line 126, in _get_response
    response = self.process_exception_by_middleware(e, request)
  File "/Users/ughestaff/.local/share/virtualenvs/Codes-vPfYgZ7o/lib/python3.10/site-packages/django/core/handlers/base.py", line 124, in _get_response
    response = wrapped_callback(request, *callback_args, **callback_kwargs)
  File "/Users/ughestaff/OneDrive - IU International University of Applied Sciences/School/Subjects/In Progress/Project Software Engineering/BloodLoof/2. Development Phase/Codes/donate/views.py", line 28, in donate
    password = request.user.password1
  File "/Users/ughestaff/.local/share/virtualenvs/Codes-vPfYgZ7o/lib/python3.10/site-packages/django/utils/functional.py", line 214, in inner
    return func(self._wrapped, *args)
AttributeError: 'User' object has no attribute 'password1'
[23/Apr/2022 19:50:53] ERROR [django.server:124] "POST /donate HTTP/1.1" 500 27
